However, the application of the last patch above failed with the following
output:

{{ mergelog | indent(4, first=True) }}

Please note that if there are subsequent patches in the series, they were not
applied because of the error message stated above.
